<?xml version="1.0"?>
<robot name="simple_robot_custom_ctlr" xmlns:xacro="http://www.ros.org/wiki/xacro"> 

    <!-- if modifications are made to this file, update the simple_robot.urdf file with the following command:
    
    rosrun xacro xacro simple_robot_custom_ctlr.xacro > simple_robot_custom_ctlr.urdf
    
    --> 
    
    <xacro:property name="PI" value="3.1415926535897931"/>
    <!-- Import all Gazebo-customization elements, including Gazebo colors -->
    <xacro:include filename="$(find simple_robot_custom_ctlr)/urdf/simple_robot_custom_ctlr.gazebo" />
    <!-- Import Rviz colors -->
    <xacro:include filename="$(find simple_robot_custom_ctlr)/urdf/materials.xacro" />
  
    <xacro:simple_robot_custom_ctlr_gazebo />
    
    <static>false</static>
	
    <!-- Start of Links - first link must be a non-inertial link -->
    <link name="base_link">
    </link> 
	
    <link name="chassis">
        <inertial>
            <mass value="1"/>
            <inertia ixx="0.004" ixy="0.0" ixz="0.0" iyy="0.004" iyz="0.0" izz="0.002"/>
        </inertial>
        <collision name='collision'>
            <geometry>
                <box size=".4 .2 .1" />
            </geometry>
        </collision>
        <visual name='visual'>
            <geometry>
                <box size=".4 .2 .1" />
            </geometry>
            <material name="orange" />
        </visual>
    </link>       

    <link name="castor">
        <inertial>
            <mass value=".1"/>
            <inertia ixx="1" ixy="0.0" ixz="0.0" iyy="1" iyz="0.0" izz="1"/>
        </inertial>
        <collision name='collision'>
            <geometry>
                <sphere radius=".05" />
            </geometry>
            <surface>
                <friction>
                    <ode>
                        <mu>0</mu>
                        <mu2>0</mu2>
                    </ode>
                </friction>
            </surface>
        </collision>              
        <visual name='visual'>
            <geometry>
                <sphere radius=".05" />
            </geometry>
        </visual>
    </link>     

    <link name="left_wheel">
        <inertial>
            <mass value=".5"/>
            <inertia ixx="1" ixy="0.0" ixz="0.0" iyy="1" iyz="0.0" izz="1"/>
        </inertial>
        <pose>0.1 0.13 0.1 0 1.5707 1.5707</pose>
        <collision name='collision'>
            <geometry>
                <cylinder radius='.1' length='.05'/>
            </geometry>
        </collision>
        <visual name='visual'>
            <geometry>
                <cylinder radius='.1' length='.05'/>
            </geometry>
	    <material name="green" />
        </visual>
    </link> 
          
    <link name="right_wheel">
        <inertial>
            <mass value=".5"/>
            <inertia ixx="1" ixy="0.0" ixz="0.0" iyy="1" iyz="0.0" izz="1"/>
        </inertial>
        <pose>0.1 0.13 0.1 0 1.5707 1.5707</pose>
        <collision name='collision'>
            <geometry>
                <cylinder radius='.1' length='.05'/>
            </geometry>
        </collision>
        <visual name='visual'>
            <geometry>
                <cylinder radius='.1' length='.05'/>
            </geometry>
	    <material name="red" />            
        </visual>
    </link>            

    <!-- Start of Joints - connecting all links together -->

    <joint name="joint0" type="fixed">
        <parent link="base_link"/>
        <child link="chassis"/>
        <origin xyz="0 0 0" rpy="0 0 0"/>
        <axis xyz="0 1 0"/>
        <dynamics damping="0.7"/>
    </joint>
    
    <joint name="joint1" type="fixed">
        <parent link="chassis"/>
        <child link="castor"/>
        <origin xyz=".15 0 -.05" rpy="0 0 0"/>
        <axis xyz="0 1 0"/>
        <dynamics damping="0.7"/>
    </joint>

    <joint type="continuous" name="wheel_left_joint">
        <parent link="chassis"/>
        <child link="left_wheel"/>
        <origin xyz="-0.1 -0.13 0" rpy="0 1.5707 1.5707"/>
        <axis xyz="0 0 1"/>
        <calibration rising="0.0"/>
        <dynamics damping="0.1" friction="0.1"/>
        <limit effort="30" velocity="30.0" />
        <safety_controller k_velocity="0" k_position="0" soft_lower_limit="0" soft_upper_limit="0" />
    </joint>

    <joint type="continuous" name="wheel_right_joint">
        <parent link="chassis"/>
        <child link="right_wheel"/>
        <origin xyz="-0.1 0.13 0" rpy="0 1.5707 1.5707"/>
        <axis xyz="0 0 1"/>
        <calibration rising="0.0"/>
        <dynamics damping="0.1" friction="0.1"/>
        <limit effort="30" velocity="30.0" />
        <safety_controller k_velocity="0" k_position="0" soft_lower_limit="0" soft_upper_limit="0" />
    </joint>
    
    <!-- Transmissions are where the ros_controller interacts -->

    <transmission name="left_wheel_transmission">
        <type>transmission_interface/SimpleTransmission</type>
        <joint name="wheel_left_joint">
            <hardwareInterface>hardware_interface/VelocityJointInterface</hardwareInterface>  
        </joint>
        <actuator name="left_wheel_actuator">
            <mechanicalReduction>1</mechanicalReduction>
            <hardwareInterface>VelocityJointInterface</hardwareInterface>
        </actuator>
    </transmission>
    
    <transmission name="right_wheel_transmission">
        <type>transmission_interface/SimpleTransmission</type>
        <joint name="wheel_right_joint">
            <hardwareInterface>hardware_interface/VelocityJointInterface</hardwareInterface>  
        </joint>
        <actuator name="right_wheel_actuator">
            <mechanicalReduction>1</mechanicalReduction>
            <hardwareInterface>VelocityJointInterface</hardwareInterface>
        </actuator>
    </transmission>
</robot>
